<?xml version="1.0"?>
<robot name="simple_6dof_manipulator">

  <!-- Material definitions -->
  <material name="gray">
    <color rgba="0.5 0.5 0.5 1.0"/>
  </material>
  <material name="blue">
    <color rgba="0.0 0.0 1.0 1.0"/>
  </material>
  <material name="green">
    <color rgba="0.0 1.0 0.0 1.0"/>
  </material>
  <material name="red">
    <color rgba="1.0 0.0 0.0 1.0"/>
  </material>
  <material name="yellow">
    <color rgba="1.0 1.0 0.0 1.0"/>
  </material>
  <material name="purple">
    <color rgba="0.5 0.0 0.5 1.0"/>
  </material>

  <!-- Base link -->
  <link name="base_link">
    <visual>
      <geometry>
        <cylinder radius="0.05" length="0.2"/>
      </geometry>
      <material name="gray"/>
    </visual>
  </link>

  <!-- Joint 1 -->
  <joint name="joint_1" type="revolute">
    <parent link="base_link"/>
    <child link="link_1"/>
    <origin rpy="0 0 0" xyz="0 0 0.1"/>
    <axis xyz="0 1 0"/>
    <limit lower="-2.8973" upper="2.8973" effort="50" velocity="2.0"/>
  </joint>

  <!-- Link 1 -->
  <link name="link_1">
    <visual>
      <geometry>
        <cylinder radius="0.05" length="0.2"/>
      </geometry>
      <material name="blue"/>
    </visual>
  </link>

  <!-- Joint 2 -->
  <joint name="joint_2" type="revolute">
    <parent link="link_1"/>
    <child link="link_2"/>
    <origin rpy="0 0 0" xyz="0 0 0.2"/>
    <axis xyz="1 0 0"/>
    <limit lower="-2.8973" upper="2.8973" effort="50" velocity="2.0"/>
  </joint>

  <!-- Link 2 -->
  <link name="link_2">
    <visual>
      <geometry>
        <cylinder radius="0.05" length="0.2"/>
      </geometry>
      <material name="green"/>
    </visual>
  </link>

  <!-- Joint 3 -->
  <joint name="joint_3" type="revolute">
    <parent link="link_2"/>
    <child link="link_3"/>
    <origin rpy="0 0 0" xyz="0 0 0.2"/>
    <axis xyz="0 1 0"/>
    <limit lower="-2.8973" upper="2.8973" effort="50" velocity="2.0"/>
  </joint>

  <!-- Link 3 -->
  <link name="link_3">
    <visual>
      <geometry>
        <cylinder radius="0.05" length="0.2"/>
      </geometry>
      <material name="red"/>
    </visual>
  </link>

  <!-- Joint 4 -->
  <joint name="joint_4" type="revolute">
    <parent link="link_3"/>
    <child link="link_4"/>
    <origin rpy="0 0 0" xyz="0 0 0.2"/>
    <axis xyz="1 0 0"/>
    <limit lower="-2.8973" upper="2.8973" effort="50" velocity="2.0"/>
  </joint>

  <!-- Link 4 -->
  <link name="link_4">
    <visual>
      <geometry>
        <cylinder radius="0.05" length="0.2"/>
      </geometry>
      <material name="yellow"/>
    </visual>
  </link>

  <!-- Joint 5 -->
  <joint name="joint_5" type="revolute">
    <parent link="link_4"/>
    <child link="link_5"/>
    <origin rpy="0 0 0" xyz="0 0 0.2"/>
    <axis xyz="0 1 0"/>
    <limit lower="-2.8973" upper="2.8973" effort="50" velocity="2.0"/>
  </joint>

  <!-- Link 5 -->
  <link name="link_5">
    <visual>
      <geometry>
        <cylinder radius="0.05" length="0.2"/>
      </geometry>
      <material name="purple"/>
    </visual>
  </link>

  <!-- Joint 6 -->
  <joint name="joint_6" type="revolute">
    <parent link="link_5"/>
    <child link="ee_link"/>
    <origin rpy="0 0 0" xyz="0 0 0.2"/>
    <axis xyz="1 0 0"/>
    <limit lower="-2.8973" upper="2.8973" effort="50" velocity="2.0"/>
  </joint>

  <!-- End-effector link -->
  <link name="ee_link">
    <visual>
      <geometry>
        <sphere radius="0.05"/>
      </geometry>
      <material name="red"/>
    </visual>
  </link>

</robot>
